Workbook

Sheet MainTablesFigures

Sheet Data
BP1: Share haven profits (excluding Puerto Rico) in total (domestic + foreign) profits
B2: Compustat (full sample, no winsorization) | H2: Compustat winsorized | O2: BEA survey | AD2: NIPA | AV2: NIPA, details | BQ2: Preferred series | BZ2: Robustness | CJ2: Tax rates computations | CQ2: Comparisons of aggregates
A3: year | B3: Profit (+) | C3: For. profits (+) | D3: Share foreign (+) | E3: Profit (all) | F3: For. profits (all) | G3: Share foreign (all) | H3: Profit (all) | I3: For. profits (all) | J3: Share foreign (all) | K3: Check | L3: Check | M3: Check | O3: Profit type return of parents | P3: Profit-type return of majority-owned affiliates (MOFA) | Q3: MOFA profit-type / (MOFA profit-type + parent profit type) | R3: Pre-tax DI equity income (no current cost adjustment) | S3: Memo: DI investmetn income with CCAdj + foreign taxes paid | T3: Pre-tax DI equity income / (Pre-tax DI equity income + parent profit type return) | U3: (Same, interpolated for missing years in the 1980) | V3: Taxes paid by majority-owned affiliates | W3: Taxes paid by parent | X3: Tax rate of parents | Y3: Ta rate of affiliates | Z3: Tax rate all | AA3: Tax rates of affiliates, corr for current-cost adj | AB3: Tax rates all, corr for current-cost adj | AD3: Total pre-tax profits (domestic + foreign), S-corp corrected | AE3: Equals: half of S-corp profits | AF3: Plus: C-corp profits | AG3: Total pre-tax profits (domestic + foreign), S-corp corrected | AH3: Equals: domestic profit | AI3: Plus: foreign pre-tax profit | AK3: Total pre-tax profits (domestic + foreign), no S-corp correction | AL3: Equals: Pre-tax domestic corporate profits | AM3: Plus: foreign pre-tax profit | AN3: Total pre-tax profits (domestic + foreign), no S-corp correction | AO3: Equals: C-corp profits | AP3: Plus: S-corps profits | AQ3: Check | AR3: Share of foreign pre-tax profit in US corporations' pre-tax profit (no S-corp correction) | AS3: Share of foreign pre-tax profit in US corporations' pre-tax profit (with S-corps correction) | AT3: Corrected CBCR data | AV3: Corporate profits in national income | AW3: Minus: Fed profits | AX3: Minus: PI dividends received from RoW | AY3: Plus: PI dividends paid to RoW | AZ3: Equals: global income of US-headquartered corp | BA3: Minus: DI equity income received from RoW, with current-cost adj | BB3: Equals: domestic income of US-headquarterd corp | BC3: Memo: DI equity income received from RoW, without current-cost adjustment | BD3: Memo: current-cost adjustment | BE3: Current-cost adjustment / DI equity income without ccadj | BF3: Memo: total DI income with CCAdj | BG3: pre-tax DI equity income without CCAdj | BI3: Foreign profit outflows | BJ3: Equals | BK3: PI dividends | BL3: DI divs + retained | BM3: Diff geographical coverage btw NIPA and BoP | BQ3: NIPA (S-corp corrected) | BR3: Ireland | BS3: [Check] | BT3: Netherlands + Luxembourg | BU3: Switzerland | BV3: Bermuda and Carribbean havens | BW3: Singapore | BX3: Check | BZ3: NIPA (no S-corp correction) | CA3: Compustat (positive profit) | CB3: Multinationals (BEA survey) | CC3: Ireland | CD3: Netherlands + Luxembourg | CE3: Switzerland | CF3: Bermuda and Carribbean havens | CG3: Singapore | CH3: Check | CJ3: Taxes paid to the US | CK3: Federal | CL3: State | CM3: Taxes paid abroad (all affiliates) | CN3: Effective US+foreign rate on global profits | CO3: (wright-zucman) | CQ3: Memo: BEA survey total profit / NIPA total profit | CR3: Memo: BEA survey foreign profit / NIPA foreign profit | CS3: Memo: BEA survey domestic profit / NIPA domestic profit (no S-corp correction) | CT3: Memo: BEA survey domestic profit / NIPA domestic profit (with S-corp correction) | CU3: BEA survey profit / NIPA profit (with S-corp correction) | CV3: Memo: Compustat total profit / NIPA total profit | CW3: Compustat foreign profits / pre-tax DI equity income at current-cost | CX3: Compustat US profit / BEA US income of parents | CY3: Compustat foreign profits / profit-type return of MOFA | CZ3: MOFA profit-type / pre-tax DI equity income at current-cost | DA3: After-tax MOFA profit-type return / DI equity income at current cost | DB3: Memo: Compustat pifo / BEA profit-type return
A4: Source / Note | B4: File compustat_all_etrs.xlsx | H4: File compustat_all_etrs.xlsx | O4: BEA USDIA survey Table I.P.1. Computed as net income + foreign income taxes paid - income from equity investments - capital gains before 1994 | P4: BEA USDIA survey Table II.F.1. Computed as net income + foreign income taxes paid - income from equity investments - capital gains before 1994 | S4: Used for country level series since BEA does not publish DI equity income by country | V4: BEA USDIA survey II.D.1 | W4: BEA USDIA survey Table I.P.1 | AB4: No correction for parents | AD4: Half of S-corp profits are removed as they do not reflect true profit but disguised wages (see Saez-Zucman 2020). Fed profits are removed | AF4: Excluding Fed | AI4: DI equity income received without current-cost adjustment, divided by 1- foreign income tax rate of MOFA, plus current-cost adjustment | AP4: Estimated based on BEA (2021) prototype estimates: https://www.bea.gov/system/files/2021-05/prototype-nipa-estimates-of-profits-for-s-corporations.pdf. Includes foreign profits (not separately identified) | BA4: ITA Table 4.2 line 12 | BB4: Excludes Puerto Rico | BC4: ITA Table 4.2 line 12 minus 16 | BD4: ITA Table 4.2 line 16 | BF4: ITA Table 4.2 line 11 | BI4: NIPA 4.1 34 + 35 | BL4: ITA 4.2 | CB4: Check exact sample | CK4: NIPA Table 3.2. 1982: OMB has much more than NIPA for fed tax, explains the gap with BEA survey: clarify why | CL4: NIPA Table 3.3
A5: 1982 | O5: =102.041+46.05-25.713-4.981 -> 117.397 | P5: =WrightZucman!O26 -> 53.575 | Q5: =P5/(P5+O5) -> 0.3133554 | R5: =BC5/(1-Y5) -> 63.745992 | T5: =R5/(R5+O5) -> 0.35190979 | U5: =T5 -> 0.35190979 | V5: 30.156 | W5: =46.05 -> 46.05 | X5: =W5/O5 -> 0.39225875 | Y5: =V5/P5 -> 0.56287448 | Z5: =(V5+W5)/(O5+P5) -> 0.44572211 | AA5: =V5/(P5/(1-BE5)) -> 0.50041468 | AB5: =(V5+W5)/(P5/(1-BE5)+O5) -> 0.42894529 | AD5: =BB5-0.5*AP5+AI5 -> 253.25677 | AE5: =0.5*AP5 -> 1.4732248 | AF5: =AD5-AE5 -> 251.78354 | AG5: =AD5 -> 253.25677 | AH5: =AG5-AI5 -> 186.03278 | AI5: =BC5/(1-Y5)+BD5 -> 67.223992 | AK5: =AL5+AM5 -> 254.72999 | AL5: =BB5 -> 187.506 | AM5: =AI5 -> 67.223992 | AN5: =AK5 -> 254.72999 | AO5: =AN5-AP5 -> 251.78354 | AP5: 2.9464497 | AQ5: =AF5-AO5 -> 0 | AR5: =Data!AM5/Data!AK5 -> 0.26390293 | AS5: =Data!AI5/Data!AG5 -> 0.26543809 | AV5: ='[1]Assets(BoP)'!$D74 -> 229.9 | AW5: 15.2 | AX5: ='[1]Assets(BoP)'!$CI74 -> 0 | AY5: =BK5 -> 4.149 | AZ5: =AV5-AW5-AX5+AY5 -> 218.849 | BA5: 31.343 | BB5: =AZ5-BA5 -> 187.506 | BC5: =BA5-BD5 -> 27.865 | BD5: 3.478 | BE5: =BD5/BA5 -> 0.11096577 | BF5: 29.469 | BG5: =BC5/(1-Y5) -> 63.745992 | BI5: ='[1]Assets(BoP)'!$Q74 -> 4.1 | BK5: =BI5-BL5 -> 4.149 | BL5: -0.049 | BM5: 0 | BP5: 1982 | BQ5: =Data!AR5*WrightZucman!B26 -> 0.03953495 | BR5: =$BQ5*WrightZucman!C26/WrightZucman!$B26 -> 0.003719024 | BS5: =WrightZucman!C26*Data!AS5-BR5 -> 2.1634007e-05 | BT5: =$BQ5*WrightZucman!D26/WrightZucman!$B26 -> 0.0049554148 | BU5: =$BQ5*WrightZucman!E26/WrightZucman!$B26 -> 0.0071917551 | BV5: =$BQ5*WrightZucman!F26/WrightZucman!$B26 -> 0.020585168 | BW5: =$BQ5*WrightZucman!G26/WrightZucman!$B26 -> 0.0030835881 | BX5: =BQ5-BR5-BT5-BU5-BV5-BW5 -> 6.0715322e-18 | BZ5: =Data!AR5*WrightZucman!B26 -> 0.03953495 | CB5: =Data!Q5*WrightZucman!B26 -> 0.046943359 | CC5: =WrightZucman!C26*Data!$Q5 -> 0.0044159278 | CD5: =WrightZucman!D26*Data!$Q5 -> 0.0058840044 | CE5: =WrightZucman!E26*Data!$Q5 -> 0.00853941 | CF5: =WrightZucman!F26*Data!$Q5 -> 0.024442599 | CG5: =WrightZucman!G26*Data!$Q5 -> 0.0036614182 | CH5: =CB5-CC5-CD5-CE5-CF5-CG5 -> -5.6378513e-18 | CJ5: =CK5+CL5 -> 47.8 | CK5: 33.8 | CL5: 14 | CM5: =BC5*Y5/(1-Y5) -> 35.880992 | CN5: =(CJ5+CM5)/AD5 -> 0.33041957 | CO5: ='[1]Assets(BoP)'!$BN74 -> 0.29823491 | CQ5: =(O5+P5)/AD5 -> 0.67509351 | CR5: =P5/AI5 -> 0.7969625 | CS5: =O5/AL5 -> 0.6260973 | CT5: =O5/(AL5-0.5*AP5) -> 0.63105547 | CU5: =(O5+P5)/AD5 -> 0.67509351 | CZ5: =P5/(BC5/(1-Y5)) -> 0.840445 | DA5: =(P5-V5)/BC5 -> 0.840445
A6: 1983 | P6: =WrightZucman!O27 -> 58.034 | U6: =U5+(U$12-U$5)/7 -> 0.35370218 | V6: 30.122 | Y6: =V6/P6 -> 0.51904056 | AA6: =V6/(P6/(1-BE6)) -> 0.47489911 | AD6: =BB6-0.5*AP6+AI6 -> 301.02016 | AE6: =0.5*AP6 -> 3.2879 | AF6: =AD6-AE6 -> 297.73226 | AG6: =AD6 -> 301.02016 | AH6: =AG6-AI6 -> 230.8431 | AI6: =BC6/(1-Y6)+BD6 -> 70.177064 | AK6: =AL6+AM6 -> 304.30806 | AL6: =BB6 -> 234.131 | AM6: =AI6 -> 70.177064 | AN6: =AK6 -> 304.30806 | AO6: =AN6-AP6 -> 297.73226 | AP6: 6.5758 | AQ6: =AF6-AO6 -> 0 | AR6: =Data!AM6/Data!AK6 -> 0.23061191 | AS6: =Data!AI6/Data!AG6 -> 0.23313077 | AV6: ='[1]Assets(BoP)'!$D75 -> 279.8 | AW6: 14.6 | AX6: ='[1]Assets(BoP)'!$CI75 -> 0 | AY6: =BK6 -> 4.242 | AZ6: =AV6-AW6-AX6+AY6 -> 269.442 | BA6: 35.311 | BB6: =AZ6-BA6 -> 234.131 | BC6: =BA6-BD6 -> 32.308 | BD6: 3.003 | BE6: =BD6/BA6 -> 0.08504432 | BF6: 31.75 | BG6: =BC6/(1-Y6) -> 67.174064 | BI6: ='[1]Assets(BoP)'!$Q75 -> 6.1 | BK6: =BI6-BL6 -> 4.242 | BL6: 1.858 | BM6: 0 | BP6: 1983 | BQ6: =Data!AR6*WrightZucman!B27 -> 0.032286621 | BR6: =$BQ6*WrightZucman!C27/WrightZucman!$B27 -> 0.0037949198 | BS6: =WrightZucman!C27*Data!AS6-BR6 -> 4.1450103e-05 | BT6: =$BQ6*WrightZucman!D27/WrightZucman!$B27 -> 0.0061910838 | BU6: =$BQ6*WrightZucman!E27/WrightZucman!$B27 -> 0.0049314088 | BV6: =$BQ6*WrightZucman!F27/WrightZucman!$B27 -> 0.01446838 | BW6: =$BQ6*WrightZucman!G27/WrightZucman!$B27 -> 0.0029008287 | BX6: =BQ6-BR6-BT6-BU6-BV6-BW6 -> 0 | BZ6: =Data!AR6*WrightZucman!B27 -> 0.032286621 | CJ6: =CK6+CL6 -> 63 | CK6: 47.1 | CL6: 15.9 | CM6: =BC6*Y6/(1-Y6) -> 34.866064 | CN6: =(CJ6+CM6)/AD6 -> 0.32511465 | CO6: ='[1]Assets(BoP)'!$BN75 -> 0.30131738 | CR6: =P6/AI6 -> 0.82696535 | CZ6: =P6/(BC6/(1-Y6)) -> 0.86393463 | DA6: =(P6-V6)/BC6 -> 0.86393463
A7: 1984 | B7: 148424.94 | C7: 47432.283 | D7: 0.31957084 | E7: 143785.13 | F7: 47667.634 | G7: 0.33151992 | H7: 143785.13 | I7: 47667.634 | J7: 0.33151992 | K7: =C7/B7-D7 -> 0 | L7: =I7/H7-J7 -> 0 | M7: =F7/E7-G7 -> 0 | P7: =WrightZucman!O28 -> 64.46 | U7: =U6+(U$12-U$5)/7 -> 0.35549457 | V7: 33.587 | Y7: =V7/P7 -> 0.52105182 | AA7: =V7/(P7/(1-BE7)) -> 0.47687751 | AD7: =BB7-0.5*AP7+AI7 -> 359.02108 | AE7: =0.5*AP7 -> 6.050477 | AF7: =AD7-AE7 -> 352.9706 | AG7: =AD7 -> 359.02108 | AH7: =AG7-AI7 -> 279.88052 | AI7: =BC7/(1-Y7)+BD7 -> 79.140552 | AK7: =AL7+AM7 -> 365.07155 | AL7: =BB7 -> 285.931 | AM7: =AI7 -> 79.140552 | AN7: =AK7 -> 365.07155 | AO7: =AN7-AP7 -> 352.9706 | AP7: 12.100954 | AQ7: =AF7-AO7 -> 0 | AR7: =Data!AM7/Data!AK7 -> 0.21678093 | AS7: =Data!AI7/Data!AG7 -> 0.22043428 | AV7: ='[1]Assets(BoP)'!$D76 -> 337.9 | AW7: 16.4 | AX7: ='[1]Assets(BoP)'!$CI76 -> 0 | AY7: =BK7 -> 4.087 | AZ7: =AV7-AW7-AX7+AY7 -> 325.587 | BA7: 39.656 | BB7: =AZ7-BA7 -> 285.931 | BC7: =BA7-BD7 -> 36.294 | BD7: 3.362 | BE7: =BD7/BA7 -> 0.0847791 | BF7: 35.326 | BG7: =BC7/(1-Y7) -> 75.778552 | BI7: ='[1]Assets(BoP)'!$Q76 -> 9.6 | BK7: =BI7-BL7 -> 4.087 | BL7: 5.513 | BM7: 0 | BP7: 1984 | BQ7: =Data!AR7*WrightZucman!B28 -> 0.028885067 | BR7: =$BQ7*WrightZucman!C28/WrightZucman!$B28 -> 0.0037195115 | BS7: =WrightZucman!C28*Data!AS7-BR7 -> 6.2683838e-05 | BT7: =$BQ7*WrightZucman!D28/WrightZucman!$B28 -> 0.0053135879 | BU7: =$BQ7*WrightZucman!E28/WrightZucman!$B28 -> 0.0050445455 | BV7: =$BQ7*WrightZucman!F28/WrightZucman!$B28 -> 0.012342321 | BW7: =$BQ7*WrightZucman!G28/WrightZucman!$B28 -> 0.0024651012 | BX7: =BQ7-BR7-BT7-BU7-BV7-BW7 -> 0 | BZ7: =Data!AR7*WrightZucman!B28 -> 0.028885067 | CA7: =Data!D7*WrightZucman!B28 -> 0.042581352 | CJ7: =CK7+CL7 -> 78 | CK7: 59.2 | CL7: 18.8 | CM7: =BC7*Y7/(1-Y7) -> 39.484552 | CN7: =(CJ7+CM7)/AD7 -> 0.32723581 | CO7: ='[1]Assets(BoP)'!$BN76 -> 0.30129275 | CR7: =P7/AI7 -> 0.81450026 | CV7: =(E7/1000000000)/AD7 -> 4.0049216e-07 | CW7: =(F7/1000)/(BC7/(1-Y7)) -> 0.6290386 | CY7: =(F7/1000000000)/P7 -> 7.3949168e-07 | CZ7: =P7/(BC7/(1-Y7)) -> 0.85063647 | DA7: =(P7-V7)/BC7 -> 0.85063647 | DB7: =(F7/1000)/P7 -> 0.73949168
A8: 1985 | B8: 140025.54 | C8: 49873.311 | D8: 0.35617295 | E8: 131427.74 | F8: 50738.892 | G8: 0.38605924 | H8: 131427.74 | I8: 50738.892 | J8: 0.38605924 | K8: =C8/B8-D8 -> 0 | L8: =I8/H8-J8 -> 0 | M8: =F8/E8-G8 -> 0 | P8: =WrightZucman!O29 -> 62.681 | U8: =U7+(U$12-U$5)/7 -> 0.35728696 | V8: 33.105 | Y8: =V8/P8 -> 0.52815048 | AA8: =V8/(P8/(1-BE8)) -> 0.45405906 | AD8: =BB8-0.5*AP8+AI8 -> 374.39414 | AE8: =0.5*AP8 -> 6.5841638 | AF8: =AD8-AE8 -> 367.80998 | AG8: =AD8 -> 374.39414 | AH8: =AG8-AI8 -> 296.91484 | AI8: =BC8/(1-Y8)+BD8 -> 77.479308 | AK8: =AL8+AM8 -> 380.97831 | AL8: =BB8 -> 303.499 | AM8: =AI8 -> 77.479308 | AN8: =AK8 -> 380.97831 | AO8: =AN8-AP8 -> 367.80998 | AP8: 13.168328 | AQ8: =AF8-AO8 -> 0 | AR8: =Data!AM8/Data!AK8 -> 0.20336934 | AS8: =Data!AI8/Data!AG8 -> 0.20694583 | AV8: ='[1]Assets(BoP)'!$D77 -> 354.5 | AW8: 16.3 | AX8: ='[1]Assets(BoP)'!$CI77 -> 0 | AY8: =BK8 -> 4.783 | AZ8: =AV8-AW8-AX8+AY8 -> 342.983 | BA8: 39.484 | BB8: =AZ8-BA8 -> 303.499 | BC8: =BA8-BD8 -> 33.945 | BD8: 5.539 | BE8: =BD8/BA8 -> 0.14028467 | BF8: 35.41 | BG8: =BC8/(1-Y8) -> 71.940308 | BI8: ='[1]Assets(BoP)'!$Q77 -> 8.7 | BK8: =BI8-BL8 -> 4.783 | BL8: 3.917 | BM8: 0 | BP8: 1985 | BQ8: =Data!AR8*WrightZucman!B29 -> 0.028554962 | BR8: =$BQ8*WrightZucman!C29/WrightZucman!$B29 -> 0.0036078989 | BS8: =WrightZucman!C29*Data!AS8-BR8 -> 6.3449169e-05 | BT8: =$BQ8*WrightZucman!D29/WrightZucman!$B29 -> 0.0059699046 | BU8: =$BQ8*WrightZucman!E29/WrightZucman!$B29 -> 0.0056162526 | BV8: =$BQ8*WrightZucman!F29/WrightZucman!$B29 -> 0.01170296 | BW8: =$BQ8*WrightZucman!G29/WrightZucman!$B29 -> 0.0016579463 | BX8: =BQ8-BR8-BT8-BU8-BV8-BW8 -> 0 | BZ8: =Data!AR8*WrightZucman!B29 -> 0.028554962 | CA8: =Data!D8*WrightZucman!B29 -> 0.050010022 | CJ8: =CK8+CL8 -> 78.7 | CK8: 58.5 | CL8: 20.2 | CM8: =BC8*Y8/(1-Y8) -> 37.995308 | CN8: =(CJ8+CM8)/AD8 -> 0.31169106 | CO8: ='[1]Assets(BoP)'!$BN77 -> 0.29848576 | CR8: =P8/AI8 -> 0.8090031 | CV8: =(E8/1000000000)/AD8 -> 3.5104111e-07 | CW8: =(F8/1000)/(BC8/(1-Y8)) -> 0.70529156 | CY8: =(F8/1000000000)/P8 -> 8.0947802e-07 | CZ8: =P8/(BC8/(1-Y8)) -> 0.8712918 | DA8: =(P8-V8)/BC8 -> 0.8712918 | DB8: =(F8/1000)/P8 -> 0.80947802
A9: 1986 | B9: 129779.73 | C9: 44262.633 | D9: 0.34105968 | E9: 115241.08 | F9: 44880.514 | G9: 0.38944893 | H9: 116659.98 | I9: 44963.068 | J9: 0.38541983 | K9: =C9/B9-D9 -> 0 | L9: =I9/H9-J9 -> 0 | M9: =F9/E9-G9 -> 0 | P9: =WrightZucman!O30 -> 56.36 | U9: =U8+(U$12-U$5)/7 -> 0.35907935 | V9: 24.454 | Y9: =V9/P9 -> 0.43388928 | AA9: =V9/(P9/(1-BE9)) -> 0.38677704 | AD9: =BB9-0.5*AP9+AI9 -> 335.62667 | AE9: =0.5*AP9 -> 6.2336909 | AF9: =AD9-AE9 -> 329.39298 | AG9: =AD9 -> 335.62667 | AH9: =AG9-AI9 -> 268.13131 | AI9: =BC9/(1-Y9)+BD9 -> 67.495359 | AK9: =AL9+AM9 -> 341.86036 | AL9: =BB9 -> 274.365 | AM9: =AI9 -> 67.495359 | AN9: =AK9 -> 341.86036 | AO9: =AN9-AP9 -> 329.39298 | AP9: 12.467382 | AQ9: =AF9-AO9 -> 0 | AR9: =Data!AM9/Data!AK9 -> 0.19743547 | AS9: =Data!AI9/Data!AG9 -> 0.20110249 | AV9: ='[1]Assets(BoP)'!$D78 -> 324.4 | AW9: 15.5 | AX9: ='[1]Assets(BoP)'!$CI78 -> 0 | AY9: =BK9 -> 5.564 | AZ9: =AV9-AW9-AX9+AY9 -> 314.464 | BA9: 40.099 | BB9: =AZ9-BA9 -> 274.365 | BC9: =BA9-BD9 -> 35.745 | BD9: 4.354 | BE9: =BD9/BA9 -> 0.10858126 | BF9: 36.938 | BG9: =BC9/(1-Y9) -> 63.141359 | BI9: ='[1]Assets(BoP)'!$Q78 -> 9.3 | BK9: =BI9-BL9 -> 5.564 | BL9: 3.736 | BM9: 0 | BP9: 1986 | BQ9: =Data!AR9*WrightZucman!B30 -> 0.029005778 | BR9: =$BQ9*WrightZucman!C30/WrightZucman!$B30 -> 0.0030266899 | BS9: =WrightZucman!C30*Data!AS9-BR9 -> 5.6215584e-05 | BT9: =$BQ9*WrightZucman!D30/WrightZucman!$B30 -> 0.0085721182 | BU9: =$BQ9*WrightZucman!E30/WrightZucman!$B30 -> 0.0056365093 | BV9: =$BQ9*WrightZucman!F30/WrightZucman!$B30 -> 0.0092026786 | BW9: =$BQ9*WrightZucman!G30/WrightZucman!$B30 -> 0.002567782 | BX9: =BQ9-BR9-BT9-BU9-BV9-BW9 -> 0 | BZ9: =Data!AR9*WrightZucman!B30 -> 0.029005778 | CA9: =Data!D9*WrightZucman!B30 -> 0.050106 | CJ9: =CK9+CL9 -> 88.7 | CK9: 66 | CL9: 22.7 | CM9: =BC9*Y9/(1-Y9) -> 27.396359 | CN9: =(CJ9+CM9)/AD9 -> 0.34590922 | CO9: ='[1]Assets(BoP)'!$BN78 -> 0.3517539 | CR9: =P9/AI9 -> 0.83502038 | CV9: =(E9/1000000000)/AD9 -> 3.433609e-07 | CW9: =(F9/1000)/(BC9/(1-Y9)) -> 0.71079424 | CY9: =(F9/1000000000)/P9 -> 7.9631856e-07 | CZ9: =P9/(BC9/(1-Y9)) -> 0.89260036 | DA9: =(P9-V9)/BC9 -> 0.89260036 | DB9: =(F9/1000)/P9 -> 0.79631856
A10: 1987 | B10: 146090.89 | C10: 48273.071 | D10: 0.33043177 | E10: 134045.91 | F10: 50815.005 | G10: 0.37908657 | H10: 138340.81 | I10: 49215.388 | J10: 0.35575465 | K10: =C10/B10-D10 -> 0 | L10: =I10/H10-J10 -> 0 | M10: =F10/E10-G10 -> 0 | P10: =WrightZucman!O31 -> 70.626 | U10: =U9+(U$12-U$5)/7 -> 0.36087174 | V10: 27.928 | Y10: =V10/P10 -> 0.39543511 | AA10: =V10/(P10/(1-BE10)) -> 0.35572642 | AD10: =BB10-0.5*AP10+AI10 -> 372.81728 | AE10: =0.5*AP10 -> 12.22623 | AF10: =AD10-AE10 -> 360.59105 | AG10: =AD10 -> 372.81728 | AH10: =AG10-AI10 -> 295.62577 | AI10: =BC10/(1-Y10)+BD10 -> 77.19151 | AK10: =AL10+AM10 -> 385.04351 | AL10: =BB10 -> 307.852 | AM10: =AI10 -> 77.19151 | AN10: =AK10 -> 385.04351 | AO10: =AN10-AP10 -> 360.59105 | AP10: 24.452461 | AQ10: =AF10-AO10 -> 0 | AR10: =Data!AM10/Data!AK10 -> 0.20047477 | AS10: =Data!AI10/Data!AG10 -> 0.20704917 | AV10: ='[1]Assets(BoP)'!$D79 -> 366 | AW10: 16.2 | AX10: ='[1]Assets(BoP)'!$CI79 -> 0 | AY10: =BK10 -> 6.649 | AZ10: =AV10-AW10-AX10+AY10 -> 356.449 | BA10: 48.597 | BB10: =AZ10-BA10 -> 307.852 | BC10: =BA10-BD10 -> 43.717 | BD10: 4.88 | BE10: =BD10/BA10 -> 0.10041772 | BF10: 46.287 | BG10: =BC10/(1-Y10) -> 72.31151 | BI10: ='[1]Assets(BoP)'!$Q79 -> 10.9 | BK10: =BI10-BL10 -> 6.649 | BL10: 4.251 | BM10: 0 | BP10: 1987 | BQ10: =Data!AR10*WrightZucman!B31 -> 0.034300925 | BR10: =$BQ10*WrightZucman!C31/WrightZucman!$B31 -> 0.0056430188 | BS10: =WrightZucman!C31*Data!AS10-BR10 -> 0.00018505807 | BT10: =$BQ10*WrightZucman!D31/WrightZucman!$B31 -> 0.010380543 | BU10: =$BQ10*WrightZucman!E31/WrightZucman!$B31 -> 0.0060716384 | BV10: =$BQ10*WrightZucman!F31/WrightZucman!$B31 -> 0.0094949185 | BW10: =$BQ10*WrightZucman!G31/WrightZucman!$B31 -> 0.0027108063 | BX10: =BQ10-BR10-BT10-BU10-BV10-BW10 -> 0 | BZ10: =Data!AR10*WrightZucman!B31 -> 0.034300925 | CA10: =Data!D10*WrightZucman!B31 -> 0.056536367 | CJ10: =CK10+CL10 -> 109.3 | CK10: 85.4 | CL10: 23.9 | CM10: =BC10*Y10/(1-Y10) -> 28.59451 | CN10: =(CJ10+CM10)/AD10 -> 0.36987156 | CO10: ='[1]Assets(BoP)'!$BN79 -> 0.38003278 | CR10: =P10/AI10 -> 0.91494518 | CV10: =(E10/1000000000)/AD10 -> 3.5954855e-07 | CW10: =(F10/1000)/(BC10/(1-Y10)) -> 0.70272361 | CY10: =(F10/1000000000)/P10 -> 7.1949431e-07 | CZ10: =P10/(BC10/(1-Y10)) -> 0.97669099 | DA10: =(P10-V10)/BC10 -> 0.97669099 | DB10: =(F10/1000)/P10 -> 0.71949431
A11: 1988 | B11: 172288.08 | C11: 63305.276 | D11: 0.36743852 | E11: 167419.38 | F11: 64231.958 | G11: 0.38365905 | H11: 167419.38 | I11: 64231.958 | J11: 0.38365905 | K11: =C11/B11-D11 -> 0 | L11: =I11/H11-J11 -> 0 | M11: =F11/E11-G11 -> 0 | P11: =WrightZucman!O32 -> 80.267 | U11: =U10+(U$12-U$5)/7 -> 0.36266413 | V11: 30.842 | Y11: =V11/P11 -> 0.38424259 | AA11: =V11/(P11/(1-BE11)) -> 0.35897413 | AD11: =BB11-0.5*AP11+AI11 -> 415.05704 | AE11: =0.5*AP11 -> 23.534675 | AF11: =AD11-AE11 -> 391.52236 | AG11: =AD11 -> 415.05704 | AH11: =AG11-AI11 -> 320.48033 | AI11: =BC11/(1-Y11)+BD11 -> 94.576711 | AK11: =AL11+AM11 -> 438.59171 | AL11: =BB11 -> 344.015 | AM11: =AI11 -> 94.576711 | AN11: =AK11 -> 438.59171 | AO11: =AN11-AP11 -> 391.52236 | AP11: 47.06935 | AQ11: =AF11-AO11 -> 0 | AR11: =Data!AM11/Data!AK11 -> 0.21563725 | AS11: =Data!AI11/Data!AG11 -> 0.22786437 | AV11: ='[1]Assets(BoP)'!$D80 -> 414.5 | AW11: 18.1 | AX11: ='[1]Assets(BoP)'!$CI80 -> 0 | AY11: =BK11 -> 7.361 | AZ11: =AV11-AW11-AX11+AY11 -> 403.761 | BA11: 59.746 | BB11: =AZ11-BA11 -> 344.015 | BC11: =BA11-BD11 -> 55.817 | BD11: 3.929 | BE11: =BD11/BA11 -> 0.065761725 | BF11: 58.445 | BG11: =BC11/(1-Y11) -> 90.647711 | BI11: ='[1]Assets(BoP)'!$Q80 -> 14.6 | BK11: =BI11-BL11 -> 7.361 | BL11: 7.239 | BM11: 0 | BP11: 1988 | BQ11: =Data!AR11*WrightZucman!B32 -> 0.030150583 | BR11: =$BQ11*WrightZucman!C32/WrightZucman!$B32 -> 0.0049404725 | BS11: =WrightZucman!C32*Data!AS11-BR11 -> 0.00028013599 | BT11: =$BQ11*WrightZucman!D32/WrightZucman!$B32 -> 0.011801792 | BU11: =$BQ11*WrightZucman!E32/WrightZucman!$B32 -> 0.0055153834 | BV11: =$BQ11*WrightZucman!F32/WrightZucman!$B32 -> 0.004814207 | BW11: =$BQ11*WrightZucman!G32/WrightZucman!$B32 -> 0.0030787284 | BX11: =BQ11-BR11-BT11-BU11-BV11-BW11 -> 0 | BZ11: =Data!AR11*WrightZucman!B32 -> 0.030150583 | CA11: =Data!D11*WrightZucman!B32 -> 0.051375565 | CJ11: =CK11+CL11 -> 119.8 | CK11: 93.8 | CL11: 26 | CM11: =BC11*Y11/(1-Y11) -> 34.830711 | CN11: =(CJ11+CM11)/AD11 -> 0.37255292 | CO11: ='[1]Assets(BoP)'!$BN80 -> 0.39111072 | CR11: =P11/AI11 -> 0.8486973 | CV11: =(E11/1000000000)/AD11 -> 4.0336474e-07 | CW11: =(F11/1000)/(BC11/(1-Y11)) -> 0.70858885 | CY11: =(F11/1000000000)/P11 -> 8.0022871e-07 | CZ11: =P11/(BC11/(1-Y11)) -> 0.88548292 | DA11: =(P11-V11)/BC11 -> 0.88548292 | DB11: =(F11/1000)/P11 -> 0.80022871
A12: 1989 | B12: 166283.96 | C12: 65590.438 | D12: 0.39444837 | E12: 159689.31 | F12: 66124.966 | G12: 0.41408513 | H12: 159689.31 | I12: 66087.898 | J12: 0.413853 | K12: =C12/B12-D12 -> 0 | L12: =I12/H12-J12 -> 0 | M12: =F12/E12-G12 -> 0 | O12: =170.663+60.446-49.377-22.056 -> 159.676 | P12: =WrightZucman!O33 -> 85.594 | Q12: =P12/(P12+O12) -> 0.34897868 | R12: =BC12/(1-Y12) -> 91.567235 | T12: =R12/(R12+O12) -> 0.36445652 | U12: =T12 -> 0.36445652 | V12: 33.291 | W12: =60.446 -> 60.446 | X12: =W12/O12 -> 0.37855407 | Y12: =V12/P12 -> 0.38894081 | Z12: =(V12+W12)/(O12+P12) -> 0.38217882 | AA12: =V12/(P12/(1-BE12)) -> 0.35216528 | AB12: =(V12+W12)/(P12/(1-BE12)+O12) -> 0.36874088 | AD12: =BB12-0.5*AP12+AI12 -> 413.26943 | AE12: =0.5*AP12 -> 24.513808 | AF12: =AD12-AE12 -> 388.75562 | AG12: =AD12 -> 413.26943 | AH12: =AG12-AI12 -> 315.85919 | AI12: =BC12/(1-Y12)+BD12 -> 97.410235 | AK12: =AL12+AM12 -> 437.78323 | AL12: =BB12 -> 340.373 | AM12: =AI12 -> 97.410235 | AN12: =AK12 -> 437.78323 | AO12: =AN12-AP12 -> 388.75562 | AP12: 49.027616 | AQ12: =AF12-AO12 -> 0 | AR12: =Data!AM12/Data!AK12 -> 0.22250792 | AS12: =Data!AI12/Data!AG12 -> 0.23570637 | AV12: ='[1]Assets(BoP)'!$D81 -> 414.3 | AW12: 20.7 | AX12: ='[1]Assets(BoP)'!$CI81 -> 0 | AY12: =BK12 -> 8.569 | AZ12: =AV12-AW12-AX12+AY12 -> 402.169 | BA12: 61.796 | BB12: =AZ12-BA12 -> 340.373 | BC12: =BA12-BD12 -> 55.953 | BD12: 5.843 | BE12: =BD12/BA12 -> 0.094553046 | BF12: 61.981 | BG12: =BC12/(1-Y12) -> 91.567235 | BI12: ='[1]Assets(BoP)'!$Q81 -> 8.4 | BK12: =BI12-BL12 -> 8.569 | BL12: -0.169 | BM12: 0 | BP12: 1989 | BQ12: =Data!AR12*WrightZucman!B33 -> 0.037366273 | BR12: =$BQ12*WrightZucman!C33/WrightZucman!$B33 -> 0.0069642581 | BS12: =WrightZucman!C33*Data!AS12-BR12 -> 0.0004130973 | BT12: =$BQ12*WrightZucman!D33/WrightZucman!$B33 -> 0.01091561 | BU12: =$BQ12*WrightZucman!E33/WrightZucman!$B33 -> 0.0055552891 | BV12: =$BQ12*WrightZucman!F33/WrightZucman!$B33 -> 0.01073104 | BW12: =$BQ12*WrightZucman!G33/WrightZucman!$B33 -> 0.0032000753 | BX12: =BQ12-BR12-BT12-BU12-BV12-BW12 -> 0 | BZ12: =Data!AR12*WrightZucman!B33 -> 0.037366273 | CA12: =Data!D12*WrightZucman!B33 -> 0.066240634 | CB12: =Data!Q12*WrightZucman!B33 -> 0.058604803 | CC12: =WrightZucman!C33*Data!$Q12 -> 0.010922657 | CD12: =WrightZucman!D33*Data!$Q12 -> 0.017119909 | CE12: =WrightZucman!E33*Data!$Q12 -> 0.0087128471 | CF12: =WrightZucman!F33*Data!$Q12 -> 0.016830432 | CG12: =WrightZucman!G33*Data!$Q12 -> 0.0050189587 | CH12: =CB12-CC12-CD12-CE12-CF12-CG12 -> 7.8062556e-18 | CJ12: =CK12+CL12 -> 119.8 | CK12: 95.6 | CL12: 24.2 | CM12: =BC12*Y12/(1-Y12) -> 35.614235 | CN12: =(CJ12+CM12)/AD12 -> 0.37606032 | CO12: ='[1]Assets(BoP)'!$BN81 -> 0.40047162 | CQ12: =(O12+P12)/AD12 -> 0.59348692 | CR12: =P12/AI12 -> 0.87869617 | CS12: =O12/AL12 -> 0.46912064 | CT12: =O12/(AL12-0.5*AP12) -> 0.50552906 | CU12: =(O12+P12)/AD12 -> 0.59348692 | CV12: =(E12/1000000000)/AD12 -> 3.8640484e-07 | CW12: =(F12/1000)/(BC12/(1-Y12)) -> 0.72214659 | CX12: =((E12-F12)/1000000000)/O12 -> 5.859637e-07 | CY12: =(F12/1000000000)/P12 -> 7.7254207e-07 | CZ12: =P12/(BC12/(1-Y12)) -> 0.93476668 | DA12: =(P12-V12)/BC12 -> 0.93476668 | DB12: =(F12/1000)/P12 -> 0.77254207
A13: 1990 | B13: 167372.79 | C13: 64101.505 | D13: 0.38298643 | E13: 156190.24 | F13: 68765.056 | G13: 0.44026474 | H13: 158439.14 | I13: 66020.98 | J13: 0.41669614 | K13: =C13/B13-D13 -> 0 | L13: =I13/H13-J13 -> 0 | M13: =F13/E13-G13 -> 0 | P13: =WrightZucman!O34 -> 84.575 | U13: =U12+(U$17-U$12)/5 -> 0.35222298 | V13: 31.693 | Y13: =V13/P13 -> 0.37473249 | AA13: =V13/(P13/(1-BE13)) -> 0.33853189 | AD13: =BB13-0.5*AP13+AI13 -> 415.42516 | AE13: =0.5*AP13 -> 24.645542 | AF13: =AD13-AE13 -> 390.77962 | AG13: =AD13 -> 415.42516 | AH13: =AG13-AI13 -> 316.48146 | AI13: =BC13/(1-Y13)+BD13 -> 98.943704 | AK13: =AL13+AM13 -> 440.0707 | AL13: =BB13 -> 341.127 | AM13: =AI13 -> 98.943704 | AN13: =AK13 -> 440.0707 | AO13: =AN13-AP13 -> 390.77962 | AP13: 49.291084 | AQ13: =AF13-AO13 -> 0 | AR13: =Data!AM13/Data!AK13 -> 0.22483593 | AS13: =Data!AI13/Data!AG13 -> 0.23817456 | AV13: ='[1]Assets(BoP)'!$D82 -> 417.7 | AW13: 21.9 | AX13: ='[1]Assets(BoP)'!$CI82 -> 0 | AY13: =BK13 -> 9.517 | AZ13: =AV13-AW13-AX13+AY13 -> 405.317 | BA13: 64.19 | BB13: =AZ13-BA13 -> 341.127 | BC13: =BA13-BD13 -> 57.989 | BD13: 6.201 | BE13: =BD13/BA13 -> 0.096603832 | BF13: 65.973 | BG13: =BC13/(1-Y13) -> 92.742704 | BI13: ='[1]Assets(BoP)'!$Q82 -> 4.8 | BK13: =BI13-BL13 -> 9.517 | BL13: -4.717 | BM13: 0 | BP13: 1990 | BQ13: =Data!AR13*WrightZucman!B34 -> 0.043972936 | BR13: =$BQ13*WrightZucman!C34/WrightZucman!$B34 -> 0.0083793419 | BS13: =WrightZucman!C34*Data!AS13-BR13 -> 0.00049711342 | BT13: =$BQ13*WrightZucman!D34/WrightZucman!$B34 -> 0.012563696 | BU13: =$BQ13*WrightZucman!E34/WrightZucman!$B34 -> 0.0068560668 | BV13: =$BQ13*WrightZucman!F34/WrightZucman!$B34 -> 0.010482153 | BW13: =$BQ13*WrightZucman!G34/WrightZucman!$B34 -> 0.0056916786 | BX13: =BQ13-BR13-BT13-BU13-BV13-BW13 -> 0 | BZ13: =Data!AR13*WrightZucman!B34 -> 0.043972936 | CA13: =Data!D13*WrightZucman!B34 -> 0.074903677 | CJ13: =CK13+CL13 -> 117 | CK13: 94.5 | CL13: 22.5 | CM13: =BC13*Y13/(1-Y13) -> 34.753704 | CN13: =(CJ13+CM13)/AD13 -> 0.36529733 | CO13: ='[1]Assets(BoP)'!$BN82 -> 0.40033205 | CR13: =P13/AI13 -> 0.854779 | CV13: =(E13/1000000000)/AD13 -> 3.7597685e-07 | CW13: =(F13/1000)/(BC13/(1-Y13)) -> 0.74146055 | CY13: =(F13/1000000000)/P13 -> 8.1306599e-07 | CZ13: =P13/(BC13/(1-Y13)) -> 0.91193157 | DA13: =(P13-V13)/BC13 -> 0.91193157 | DB13: =(F13/1000)/P13 -> 0.81306599
A14: 1991 | B14: 135501.25 | C14: 49338.892 | D14: 0.36412132 | E14: 108264.38 | F14: 52632.041 | G14: 0.48614365 | H14: 116142.38 | I14: 49483.292 | J14: 0.42605715 | K14: =C14/B14-D14 -> 0 | L14: =I14/H14-J14 -> 0 | M14: =F14/E14-G14 -> 0 | P14: =WrightZucman!O35 -> 73.301 | U14: =U13+(U$17-U$12)/5 -> 0.33998943 | V14: 26.877 | Y14: =V14/P14 -> 0.36666621 | AA14: =V14/(P14/(1-BE14)) -> 0.33353072 | AD14: =BB14-0.5*AP14+AI14 -> 450.29241 | AE14: =0.5*AP14 -> 21.480688 | AF14: =AD14-AE14 -> 428.81172 | AG14: =AD14 -> 450.29241 | AH14: =AG14-AI14 -> 362.56631 | AI14: =BC14/(1-Y14)+BD14 -> 87.726099 | AK14: =AL14+AM14 -> 471.7731 | AL14: =BB14 -> 384.047 | AM14: =AI14 -> 87.726099 | AN14: =AK14 -> 471.7731 | AO14: =AN14-AP14 -> 428.81172 | AP14: 42.961375 | AQ14: =AF14-AO14 -> 0 | AR14: =Data!AM14/Data!AK14 -> 0.18594977 | AS14: =Data!AI14/Data!AG14 -> 0.19482029 | AV14: ='[1]Assets(BoP)'!$D83 -> 452.6 | AW14: 20.8 | AX14: ='[1]Assets(BoP)'!$CI83 -> 0 | AY14: =BK14 -> 9.711 | AZ14: =AV14-AW14-AX14+AY14 -> 441.511 | BA14: 57.464 | BB14: =AZ14-BA14 -> 384.047 | BC14: =BA14-BD14 -> 52.271 | BD14: 5.193 | BE14: =BD14/BA14 -> 0.090369623 | BF14: 58.717 | BG14: =BC14/(1-Y14) -> 82.533099 | BI14: ='[1]Assets(BoP)'!$Q83 -> -1 | BK14: =BI14-BL14 -> 9.711 | BL14: -10.711 | BM14: 0 | BP14: 1991 | BQ14: =Data!AR14*WrightZucman!B35 -> 0.038729282 | BR14: =$BQ14*WrightZucman!C35/WrightZucman!$B35 -> 0.0076459066 | BS14: =WrightZucman!C35*Data!AS14-BR14 -> 0.00036473929 | BT14: =$BQ14*WrightZucman!D35/WrightZucman!$B35 -> 0.010898081 | BU14: =$BQ14*WrightZucman!E35/WrightZucman!$B35 -> 0.0070878113 | BV14: =$BQ14*WrightZucman!F35/WrightZucman!$B35 -> 0.0087164351 | BW14: =$BQ14*WrightZucman!G35/WrightZucman!$B35 -> 0.0043810487 | BX14: =BQ14-BR14-BT14-BU14-BV14-BW14 -> 0 | BZ14: =Data!AR14*WrightZucman!B35 -> 0.038729282 | CA14: =Data!D14*WrightZucman!B35 -> 0.075838531 | CJ14: =CK14+CL14 -> 112.8 | CK14: 89.2 | CL14: 23.6 | CM14: =BC14*Y14/(1-Y14) -> 30.262099 | CN14: =(CJ14+CM14)/AD14 -> 0.31770933 | CO14: ='[1]Assets(BoP)'!$BN83 -> 0.34828754 | CR14: =P14/AI14 -> 0.83556662 | CV14: =(E14/1000000000)/AD14 -> 2.4043128e-07 | CW14: =(F14/1000)/(BC14/(1-Y14)) -> 0.63770829 | CY14: =(F14/1000000000)/P14 -> 7.1802623e-07 | CZ14: =P14/(BC14/(1-Y14)) -> 0.88814065 | DA14: =(P14-V14)/BC14 -> 0.88814065 | DB14: =(F14/1000)/P14 -> 0.71802623
A15: 1992 | B15: 157749.97 | C15: 48112.432 | D15: 0.3049917 | E15: 125440.12 | F15: 47824.37 | G15: 0.38125258 | H15: 141441.82 | I15: 46567.968 | J15: 0.32923763 | K15: =C15/B15-D15 -> 0 | L15: =I15/H15-J15 -> 0 | M15: =F15/E15-G15 -> 0 | P15: =WrightZucman!O36 -> 69.447 | U15: =U14+(U$17-U$12)/5 -> 0.32775589 | V15: 26.686 | Y15: =V15/P15 -> 0.38426426 | AA15: =V15/(P15/(1-BE15)) -> 0.34595034 | AD15: =BB15-0.5*AP15+AI15 -> 467.32345 | AE15: =0.5*AP15 -> 32.913532 | AF15: =AD15-AE15 -> 434.40992 | AG15: =AD15 -> 467.32345 | AH15: =AG15-AI15 -> 379.30547 | AI15: =BC15/(1-Y15)+BD15 -> 88.017985 | AK15: =AL15+AM15 -> 500.23698 | AL15: =BB15 -> 412.219 | AM15: =AI15 -> 88.017985 | AN15: =AK15 -> 500.23698 | AO15: =AN15-AP15 -> 434.40992 | AP15: 65.827065 | AQ15: =AF15-AO15 -> 0 | AR15: =Data!AM15/Data!AK15 -> 0.17595257 | AS15: =Data!AI15/Data!AG15 -> 0.18834489 | AV15: ='[1]Assets(BoP)'!$D84 -> 477.2 | AW15: 18.4 | AX15: ='[1]Assets(BoP)'!$CI84 -> 0 | AY15: =BK15 -> 9.774 | AZ15: =AV15-AW15-AX15+AY15 -> 468.574 | BA15: 56.355 | BB15: =AZ15-BA15 -> 412.219 | BC15: =BA15-BD15 -> 50.736 | BD15: 5.619 | BE15: =BD15/BA15 -> 0.099707213 | BF15: 57.539 | BG15: =BC15/(1-Y15) -> 82.398985 | BI15: ='[1]Assets(BoP)'!$Q84 -> 5.2 | BK15: =BI15-BL15 -> 9.774 | BL15: -4.574 | BM15: 0 | BP15: 1992 | BQ15: =Data!AR15*WrightZucman!B36 -> 0.034173518 | BR15: =$BQ15*WrightZucman!C36/WrightZucman!$B36 -> 0.0087790065 | BS15: =WrightZucman!C36*Data!AS15-BR15 -> 0.00061830433 | BT15: =$BQ15*WrightZucman!D36/WrightZucman!$B36 -> 0.0095948334 | BU15: =$BQ15*WrightZucman!E36/WrightZucman!$B36 -> 0.003805503 | BV15: =$BQ15*WrightZucman!F36/WrightZucman!$B36 -> 0.0081785377 | BW15: =$BQ15*WrightZucman!G36/WrightZucman!$B36 -> 0.0038156375 | BX15: =BQ15-BR15-BT15-BU15-BV15-BW15 -> 0 | BZ15: =Data!AR15*WrightZucman!B36 -> 0.034173518 | CA15: =Data!D15*WrightZucman!B36 -> 0.059235504 | CJ15: =CK15+CL15 -> 126.4 | CK15: 102 | CL15: 24.4 | CM15: =BC15*Y15/(1-Y15) -> 31.662985 | CN15: =(CJ15+CM15)/AD15 -> 0.33823037 | CO15: ='[1]Assets(BoP)'!$BN84 -> 0.37780778 | CR15: =P15/AI15 -> 0.7890092 | CV15: =(E15/1000000000)/AD15 -> 2.6842248e-07 | CW15: =(F15/1000)/(BC15/(1-Y15)) -> 0.58039999 | CY15: =(F15/1000000000)/P15 -> 6.8864559e-07 | CZ15: =P15/(BC15/(1-Y15)) -> 0.84281378 | DA15: =(P15-V15)/BC15 -> 0.84281378 | DB15: =(F15/1000)/P15 -> 0.68864559
A16: 1993 | B16: 178070.18 | C16: 50243.837 | D16: 0.2821575 | E16: 147436.37 | F16: 46877.183 | G16: 0.31794858 | H16: 157103.17 | I16: 49368.896 | J16: 0.31424507 | K16: =C16/B16-D16 -> 0 | L16: =I16/H16-J16 -> 0 | M16: =F16/E16-G16 -> 0 | P16: =WrightZucman!O37 -> 73.787 | U16: =U15+(U$17-U$12)/5 -> 0.31552235 | V16: 24.316 | Y16: =V16/P16 -> 0.32954314 | AA16: =V16/(P16/(1-BE16)) -> 0.29585249 | AD16: =BB16-0.5*AP16+AI16 -> 513.45903 | AE16: =0.5*AP16 -> 33.460841 | AF16: =AD16-AE16 -> 479.99818 | AG16: =AD16 -> 513.45903 | AH16: =AG16-AI16 -> 418.96216 | AI16: =BC16/(1-Y16)+BD16 -> 94.496867 | AK16: =AL16+AM16 -> 546.91987 | AL16: =BB16 -> 452.423 | AM16: =AI16 -> 94.496867 | AN16: =AK16 -> 546.91987 | AO16: =AN16-AP16 -> 479.99818 | AP16: 66.921683 | AQ16: =AF16-AO16 -> 0 | AR16: =Data!AM16/Data!AK16 -> 0.1727801 | AS16: =Data!AI16/Data!AG16 -> 0.18403974 | AV16: ='[1]Assets(BoP)'!$D85 -> 524.6 | AW16: 16.8 | AX16: ='[1]Assets(BoP)'!$CI85 -> 0 | AY16: =BK16 -> 10.188 | AZ16: =AV16-AW16-AX16+AY16 -> 517.988 | BA16: 65.565 | BB16: =AZ16-BA16 -> 452.423 | BC16: =BA16-BD16 -> 58.862 | BD16: 6.703 | BE16: =BD16/BA16 -> 0.10223442 | BF16: 67.245 | BG16: =BC16/(1-Y16) -> 87.793867 | BI16: ='[1]Assets(BoP)'!$Q85 -> 12 | BK16: =BI16-BL16 -> 10.188 | BL16: 1.812 | BM16: 0 | BP16: 1993 | BQ16: =Data!AR16*WrightZucman!B37 -> 0.033246125 | BR16: =$BQ16*WrightZucman!C37/WrightZucman!$B37 -> 0.0077905238 | BS16: =WrightZucman!C37*Data!AS16-BR16 -> 0.00050768896 | BT16: =$BQ16*WrightZucman!D37/WrightZucman!$B37 -> 0.0072636624 | BU16: =$BQ16*WrightZucman!E37/WrightZucman!$B37 -> 0.0046715043 | BV16: =$BQ16*WrightZucman!F37/WrightZucman!$B37 -> 0.0075727544 | BW16: =$BQ16*WrightZucman!G37/WrightZucman!$B37 -> 0.0059476797 | BX16: =BQ16-BR16-BT16-BU16-BV16-BW16 -> 0 | BZ16: =Data!AR16*WrightZucman!B37 -> 0.033246125 | CA16: =Data!D16*WrightZucman!B37 -> 0.054292385 | CJ16: =CK16+CL16 -> 149.4 | CK16: 122.5 | CL16: 26.9 | CM16: =BC16*Y16/(1-Y16) -> 28.931867 | CN16: =(CJ16+CM16)/AD16 -> 0.3473147 | CO16: ='[1]Assets(BoP)'!$BN85 -> 0.38705472 | CR16: =P16/AI16 -> 0.7808407 | CV16: =(E16/1000000000)/AD16 -> 2.8714339e-07 | CW16: =(F16/1000)/(BC16/(1-Y16)) -> 0.53394599 | CY16: =(F16/1000000000)/P16 -> 6.3530409e-07 | CZ16: =P16/(BC16/(1-Y16)) -> 0.84045734 | DA16: =(P16-V16)/BC16 -> 0.84045734 | DB16: =(F16/1000)/P16 -> 0.63530409
A17: 1994 | B17: 239721.16 | C17: 73372.816 | D17: 0.30607568 | E17: 230103.77 | F17: 72384.577 | G17: 0.31457363 | H17: 231342.66 | I17: 73160.513 | J17: 0.31624307 | K17: =C17/B17-D17 -> 0 | L17: =I17/H17-J17 -> 0 | M17: =F17/E17-G17 -> 0 | O17: 238.853 | P17: =WrightZucman!O38 -> 84.9 | Q17: =P17/(P17+O17) -> 0.26223695 | R17: =BC17/(1-Y17) -> 103.97628 | T17: =R17/(R17+O17) -> 0.30328881 | U17: =T17 -> 0.30328881 | V17: 29.277 | W17: 93.957 | X17: =W17/O17 -> 0.39336747 | Y17: =V17/P17 -> 0.34484099 | Z17: =(V17+W17)/(O17+P17) -> 0.38064203 | AA17: =V17/(P17/(1-BE17)) -> 0.31305773 | AB17: =(V17+W17)/(P17/(1-BE17)+O17) -> 0.37077076 | AD17: =BB17-0.5*AP17+AI17 -> 605.6273 | AE17: =0.5*AP17 -> 47.872983 | AF17: =AD17-AE17 -> 557.75432 | AG17: =AD17 -> 605.6273 | AH17: =AG17-AI17 -> 494.73502 | AI17: =BC17/(1-Y17)+BD17 -> 110.89228 | AK17: =AL17+AM17 -> 653.50028 | AL17: =BB17 -> 542.608 | AM17: =AI17 -> 110.89228 | AN17: =AK17 -> 653.50028 | AO17: =AN17-AP17 -> 557.75432 | AP17: 95.745966 | AQ17: =AF17-AO17 -> 0 | AR17: =Data!AM17/Data!AK17 -> 0.16968973 | AS17: =Data!AI17/Data!AG17 -> 0.18310318 | AV17: ='[1]Assets(BoP)'!$D86 -> 624.8 | AW17: 18.6 | AX17: ='[1]Assets(BoP)'!$CI86 -> 0 | AY17: =BK17 -> 11.445 | AZ17: =AV17-AW17-AX17+AY17 -> 617.645 | BA17: 75.037 | BB17: =AZ17-BA17 -> 542.608 | BC17: =BA17-BD17 -> 68.121 | BD17: 6.916 | BE17: =BD17/BA17 -> 0.092167864 | BF17: 77.344 | BG17: =BC17/(1-Y17) -> 103.97628 | BI17: ='[1]Assets(BoP)'!$Q86 -> 26.6 | BK17: =BI17-BL17 -> 11.445 | BL17: 15.155 | BM17: 0 | BP17: 1994 | BQ17: =Data!AR17*WrightZucman!B38 -> 0.032121126 | BR17: =$BQ17*WrightZucman!C38/WrightZucman!$B38 -> 0.0077269786 | BS17: =WrightZucman!C38*Data!AS17-BR17 -> 0.00061079399 | BT17: =$BQ17*WrightZucman!D38/WrightZucman!$B38 -> 0.0079508331 | BU17: =$BQ17*WrightZucman!E38/WrightZucman!$B38 -> 0.0046829568 | BV17: =$BQ17*WrightZucman!F38/WrightZucman!$B38 -> 0.0060580632 | BW17: =$BQ17*WrightZucman!G38/WrightZucman!$B38 -> 0.0057022944 | BX17: =BQ17-BR17-BT17-BU17-BV17-BW17 -> 0 | BZ17: =Data!AR17*WrightZucman!B38 -> 0.032121126 | CA17: =Data!D17*WrightZucman!B38 -> 0.05793807 | CB17: =Data!Q17*WrightZucman!B38 -> 0.049639694 | CC17: =WrightZucman!C38*Data!$Q17 -> 0.011941202 | CD17: =WrightZucman!D38*Data!$Q17 -> 0.012287145 | CE17: =WrightZucman!E38*Data!$Q17 -> 0.0072369986 | CF17: =WrightZucman!F38*Data!$Q17 -> 0.0093620754 | CG17: =WrightZucman!G38*Data!$Q17 -> 0.0088122736 | CH17: =CB17-CC17-CD17-CE17-CF17-CG17 -> 0 | CJ17: =CK17+CL17 -> 166.3 | CK17: 136.3 | CL17: 30 | CM17: =BC17*Y17/(1-Y17) -> 35.855285 | CN17: =(CJ17+CM17)/AD17 -> 0.33379487 | CO17: ='[1]Assets(BoP)'!$BN86 -> 0.3642685 | CQ17: =(O17+P17)/AD17 -> 0.53457465 | CR17: =P17/AI17 -> 0.76560781 | CS17: =O17/AL17 -> 0.44019439 | CT17: =O17/(AL17-0.5*AP17) -> 0.48278976 | CU17: =(O17+P17)/AD17 -> 0.53457465 | CV17: =(E17/1000000000)/AD17 -> 3.7994286e-07 | CW17: =(F17/1000)/(BC17/(1-Y17)) -> 0.69616429 | CX17: =((E17-F17)/1000000000)/O17 -> 6.6031907e-07 | CY17: =(F17/1000000000)/P17 -> 8.525863e-07 | CZ17: =P17/(BC17/(1-Y17)) -> 0.81653235 | DA17: =(P17-V17)/BC17 -> 0.81653235 | DB17: =(F17/1000)/P17 -> 0.8525863
A18: 1995 | B18: 272903.04 | C18: 94225.192 | D18: 0.34526985 | E18: 255810.62 | F18: 93586.162 | G18: 0.36584159 | H18: 257936.19 | I18: 94016.584 | J18: 0.36449552 | K18: =C18/B18-D18 -> 0 | L18: =I18/H18-J18 -> 0 | M18: =F18/E18-G18 -> 0 | O18: 266.285 | P18: =WrightZucman!O39 -> 114.88 | Q18: =P18/(P18+O18) -> 0.30139179 | R18: =BC18/(1-Y18) -> 130.04804 | T18: =R18/(R18+O18) -> 0.32812819 | U18: =T18 -> 0.32812819 | V18: 38.801 | Y18: =V18/P18 -> 0.33775244 | AA18: =V18/(P18/(1-BE18)) -> 0.31345464 | AD18: =BB18-0.5*AP18+AI18 -> 687.21747 | AE18: =0.5*AP18 -> 52.024572 | AF18: =AD18-AE18 -> 635.1929 | AG18: =AD18 -> 687.21747 | AH18: =AG18-AI18 -> 550.49343 | AI18: =BC18/(1-Y18)+BD18 -> 136.72404 | AK18: =AL18+AM18 -> 739.24204 | AL18: =BB18 -> 602.518 | AM18: =AI18 -> 136.72404 | AN18: =AK18 -> 739.24204 | AO18: =AN18-AP18 -> 635.1929 | AP18: 104.04914 | AQ18: =AF18-AO18 -> 0 | AR18: =Data!AM18/Data!AK18 -> 0.18495166 | AS18: =Data!AI18/Data!AG18 -> 0.1989531 | AV18: ='[1]Assets(BoP)'!$D87 -> 706.2 | AW18: 23.1 | AX18: ='[1]Assets(BoP)'!$CI87 -> 0 | AY18: =BK18 -> 12.218 | AZ18: =AV18-AW18-AX18+AY18 -> 695.318 | BA18: 92.8 | BB18: =AZ18-BA18 -> 602.518 | BC18: =BA18-BD18 -> 86.124 | BD18: 6.676 | BE18: =BD18/BA18 -> 0.071939655 | BF18: 95.26 | BG18: =BC18/(1-Y18) -> 130.04804 | BI18: ='[1]Assets(BoP)'!$Q87 -> 34.4 | BK18: =BI18-BL18 -> 12.218 | BL18: 22.182 | BM18: 0 | BP18: 1995 | BQ18: =Data!AR18*WrightZucman!B39 -> 0.038560039 | BR18: =$BQ18*WrightZucman!C39/WrightZucman!$B39 -> 0.0084265059 | BS18: =WrightZucman!C39*Data!AS18-BR18 -> 0.00063791359 | BT18: =$BQ18*WrightZucman!D39/WrightZucman!$B39 -> 0.010955746 | BU18: =$BQ18*WrightZucman!E39/WrightZucman!$B39 -> 0.0057829593 | BV18: =$BQ18*WrightZucman!F39/WrightZucman!$B39 -> 0.007017795 | BW18: =$BQ18*WrightZucman!G39/WrightZucman!$B39 -> 0.0063770328 | BX18: =BQ18-BR18-BT18-BU18-BV18-BW18 -> 0 | BZ18: =Data!AR18*WrightZucman!B39 -> 0.038560039 | CA18: =Data!D18*WrightZucman!B39 -> 0.071984316 | CB18: =Data!Q18*WrightZucman!B39 -> 0.062836304 | CC18: =WrightZucman!C39*Data!$Q18 -> 0.013731586 | CD18: =WrightZucman!D39*Data!$Q18 -> 0.017853161 | CE18: =WrightZucman!E39*Data!$Q18 -> 0.0094237404 | CF18: =WrightZucman!F39*Data!$Q18 -> 0.011435992 | CG18: =WrightZucman!G39*Data!$Q18 -> 0.010391825 | CH18: =CB18-CC18-CD18-CE18-CF18-CG18 -> 0 | CJ18: =CK18+CL18 -> 187.6 | CK18: 155.9 | CL18: 31.7 | CM18: =BC18*Y18/(1-Y18) -> 43.924044 | CN18: =(CJ18+CM18)/AD18 -> 0.33690069 | CO18: ='[1]Assets(BoP)'!$BN87 -> 0.36090362 | CQ18: =(O18+P18)/AD18 -> 0.55464975 | CR18: =P18/AI18 -> 0.84023261 | CS18: =O18/AL18 -> 0.4419536 | CT18: =O18/(AL18-0.5*AP18) -> 0.48372058 | CU18: =(O18+P18)/AD18 -> 0.55464975 | CV18: =(E18/1000000000)/AD18 -> 3.7224114e-07 | CW18: =(F18/1000)/(BC18/(1-Y18)) -> 0.7196276 | CX18: =((E18-F18)/1000000000)/O18 -> 6.0921364e-07 | CY18: =(F18/1000000000)/P18 -> 8.1464278e-07 | CZ18: =P18/(BC18/(1-Y18)) -> 0.88336584 | DA18: =(P18-V18)/BC18 -> 0.88336584 | DB18: =(F18/1000)/P18 -> 0.81464278
A19: 1996 | B19: 315709.02 | C19: 105506.97 | D19: 0.33419057 | E19: 299652.96 | F19: 104925.67 | G19: 0.3501573 | H19: 300642.76 | I19: 104971.66 | J19: 0.34915746 | K19: =C19/B19-D19 -> 0 | L19: =I19/H19-J19 -> 0 | M19: =F19/E19-G19 -> 0 | O19: 327.324 | P19: =WrightZucman!O40 -> 130.287 | Q19: =P19/(P19+O19) -> 0.28471125 | R19: =BC19/(1-Y19) -> 142.16969 | T19: =R19/(R19+O19) -> 0.30281491 | U19: =T19 -> 0.30281491 | V19: 45.192 | Y19: =V19/P19 -> 0.346865 | AA19: =V19/(P19/(1-BE19)) -> 0.32107678 | AD19: =BB19-0.5*AP19+AI19 -> 766.52519 | AE19: =0.5*AP19 -> 62.996499 | AF19: =AD19-AE19 -> 703.52869 | AG19: =AD19 -> 766.52519 | AH19: =AG19-AI19 -> 616.8975 | AI19: =BC19/(1-Y19)+BD19 -> 149.62769 | AK19: =AL19+AM19 -> 829.52169 | AL19: =BB19 -> 679.894 | AM19: =AI19 -> 149.62769 | AN19: =AK19 -> 829.52169 | AO19: =AN19-AP19 -> 703.52869 | AP19: 125.993 | AQ19: =AF19-AO19 -> 0 | AR19: =Data!AM19/Data!AK19 -> 0.18037827 | AS19: =Data!AI19/Data!AG19 -> 0.19520257 | AV19: ='[1]Assets(BoP)'!$D88 -> 789.5 | AW19: 22.7 | AX19: ='[1]Assets(BoP)'!$CI88 -> 0 | AY19: =BK19 -> 13.408 | AZ19: =AV19-AW19-AX19+AY19 -> 780.208 | BA19: 100.314 | BB19: =AZ19-BA19 -> 679.894 | BC19: =BA19-BD19 -> 92.856 | BD19: 7.458 | BE19: =BD19/BA19 -> 0.074346552 | BF19: 102.505 | BG19: =BC19/(1-Y19) -> 142.16969 | BI19: ='[1]Assets(BoP)'!$Q88 -> 37.4 | BK19: =BI19-BL19 -> 13.408 | BL19: 23.992 | BM19: 0 | BP19: 1996 | BQ19: =Data!AR19*WrightZucman!B40 -> 0.035587768 | BR19: =$BQ19*WrightZucman!C40/WrightZucman!$B40 -> 0.0078513219 | BS19: =WrightZucman!C40*Data!AS19-BR19 -> 0.00064525706 | BT19: =$BQ19*WrightZucman!D40/WrightZucman!$B40 -> 0.0086930789 | BU19: =$BQ19*WrightZucman!E40/WrightZucman!$B40 -> 0.0040924894 | BV19: =$BQ19*WrightZucman!F40/WrightZucman!$B40 -> 0.0067866655 | BW19: =$BQ19*WrightZucman!G40/WrightZucman!$B40 -> 0.0081642119 | BX19: =BQ19-BR19-BT19-BU19-BV19-BW19 -> 0 | BZ19: =Data!AR19*WrightZucman!B40 -> 0.035587768 | CA19: =Data!D19*WrightZucman!B40 -> 0.065934195 | CB19: =Data!Q19*WrightZucman!B40 -> 0.056172164 | CC19: =WrightZucman!C40*Data!$Q19 -> 0.012392622 | CD19: =WrightZucman!D40*Data!$Q19 -> 0.013721261 | CE19: =WrightZucman!E40*Data!$Q19 -> 0.0064596349 | CF19: =WrightZucman!F40*Data!$Q19 -> 0.010712155 | CG19: =WrightZucman!G40*Data!$Q19 -> 0.012886491 | CH19: =CB19-CC19-CD19-CE19-CF19-CG19 -> 0 | CJ19: =CK19+CL19 -> 203.5 | CK19: 170.5 | CL19: 33 | CM19: =BC19*Y19/(1-Y19) -> 49.313689 | CN19: =(CJ19+CM19)/AD19 -> 0.32981785 | CO19: ='[1]Assets(BoP)'!$BN88 -> 0.36179959 | CQ19: =(O19+P19)/AD19 -> 0.59699408 | CR19: =P19/AI19 -> 0.87074124 | CS19: =O19/AL19 -> 0.48143387 | CT19: =O19/(AL19-0.5*AP19) -> 0.53059706 | CU19: =(O19+P19)/AD19 -> 0.59699408 | CV19: =(E19/1000000000)/AD19 -> 3.9092383e-07 | CW19: =(F19/1000)/(BC19/(1-Y19)) -> 0.73803124 | CX19: =((E19-F19)/1000000000)/O19 -> 5.9490685e-07 | CY19: =(F19/1000000000)/P19 -> 8.0534261e-07 | CZ19: =P19/(BC19/(1-Y19)) -> 0.91641897 | DA19: =(P19-V19)/BC19 -> 0.91641897 | DB19: =(F19/1000)/P19 -> 0.80534261
A20: 1997 | B20: 331969.38 | C20: 109998.45 | D20: 0.33135118 | E20: 313159.9 | F20: 108794.38 | G20: 0.34740839 | H20: 315072.49 | I20: 108904.21 | J20: 0.34564811 | K20: =C20/B20-D20 -> 0 | L20: =I20/H20-J20 -> 0 | M20: =F20/E20-G20 -> 0 | O20: 338.315 | P20: =WrightZucman!O41 -> 144.277 | Q20: =P20/(P20+O20) -> 0.29896268 | R20: =BC20/(1-Y20) -> 155.43308 | T20: =R20/(R20+O20) -> 0.31480239 | U20: =T20 -> 0.31480239 | V20: 47.58 | Y20: =V20/P20 -> 0.32978229 | AA20: =V20/(P20/(1-BE20)) -> 0.30346566 | AD20: =BB20-0.5*AP20+AI20 -> 835.16929 | AE20: =0.5*AP20 -> 75.619788 | AF20: =AD20-AE20 -> 759.5495 | AG20: =AD20 -> 835.16929 | AH20: =AG20-AI20 -> 670.70221 | AI20: =BC20/(1-Y20)+BD20 -> 164.46708 | AK20: =AL20+AM20 -> 910.78908 | AL20: =BB20 -> 746.322 | AM20: =AI20 -> 164.46708 | AN20: =AK20 -> 910.78908 | AO20: =AN20-AP20 -> 759.5495 | AP20: 151.23958 | AQ20: =AF20-AO20 -> 0 | AR20: =Data!AM20/Data!AK20 -> 0.18057647 | AS20: =Data!AI20/Data!AG20 -> 0.19692663 | AV20: ='[1]Assets(BoP)'!$D89 -> 869.7 | AW20: 24.4 | AX20: ='[1]Assets(BoP)'!$CI89 -> 0 | AY20: =BK20 -> 14.23 | AZ20: =AV20-AW20-AX20+AY20 -> 859.53 | BA20: 113.208 | BB20: =AZ20-BA20 -> 746.322 | BC20: =BA20-BD20 -> 104.174 | BD20: 9.034 | BE20: =BD20/BA20 -> 0.079800014 | BF20: 115.323 | BG20: =BC20/(1-Y20) -> 155.43308 | BI20: ='[1]Assets(BoP)'!$Q89 -> 48 | BK20: =BI20-BL20 -> 14.23 | BL20: 33.77 | BM20: 0 | BP20: 1997 | BQ20: =Data!AR20*WrightZucman!B41 -> 0.040587996 | BR20: =$BQ20*WrightZucman!C41/WrightZucman!$B41 -> 0.010166712 | BS20: =WrightZucman!C41*Data!AS20-BR20 -> 0.00092053742 | BT20: =$BQ20*WrightZucman!D41/WrightZucman!$B41 -> 0.0098412968 | BU20: =$BQ20*WrightZucman!E41/WrightZucman!$B41 -> 0.0041953487 | BV20: =$BQ20*WrightZucman!F41/WrightZucman!$B41 -> 0.010030288 | BW20: =$BQ20*WrightZucman!G41/WrightZucman!$B41 -> 0.0063543513 | BX20: =BQ20-BR20-BT20-BU20-BV20-BW20 -> 0 | BZ20: =Data!AR20*WrightZucman!B41 -> 0.040587996 | CA20: =Data!D20*WrightZucman!B41 -> 0.074477481 | CB20: =Data!Q20*WrightZucman!B41 -> 0.06719755 | CC20: =WrightZucman!C41*Data!$Q20 -> 0.016832024 | CD20: =WrightZucman!D41*Data!$Q20 -> 0.016293266 | CE20: =WrightZucman!E41*Data!$Q20 -> 0.0069458259 | CF20: =WrightZucman!F41*Data!$Q20 -> 0.01660616 | CG20: =WrightZucman!G41*Data!$Q20 -> 0.010520274 | CH20: =CB20-CC20-CD20-CE20-CF20-CG20 -> 0 | CJ20: =CK20+CL20 -> 216.4 | CK20: 182.3 | CL20: 34.1 | CM20: =BC20*Y20/(1-Y20) -> 51.259076 | CN20: =(CJ20+CM20)/AD20 -> 0.32048482 | CO20: ='[1]Assets(BoP)'!$BN89 -> 0.35102871 | CQ20: =(O20+P20)/AD20 -> 0.57783734 | CR20: =P20/AI20 -> 0.8772394 | CS20: =O20/AL20 -> 0.4533097 | CT20: =O20/(AL20-0.5*AP20) -> 0.50441909 | CU20: =(O20+P20)/AD20 -> 0.57783734 | CV20: =(E20/1000000000)/AD20 -> 3.7496578e-07 | CW20: =(F20/1000)/(BC20/(1-Y20)) -> 0.69994353 | CX20: =((E20-F20)/1000000000)/O20 -> 6.0406876e-07 | CY20: =(F20/1000000000)/P20 -> 7.5406598e-07 | CZ20: =P20/(BC20/(1-Y20)) -> 0.92822585 | DA20: =(P20-V20)/BC20 -> 0.92822585 | DB20: =(F20/1000)/P20 -> 0.75406598
A21: 1998 | B21: 311195.33 | C21: 90601.352 | D21: 0.29113982 | E21: 277527.31 | F21: 89122.299 | G21: 0.32112983 | H21: 281837.76 | I21: 88377.677 | J21: 0.31357642 | K21: =C21/B21-D21 -> 0 | L21: =I21/H21-J21 -> 0 | M21: =F21/E21-G21 -> 0 | O21: =[2]A!$D$16/1000 -> 353.618 | P21: =WrightZucman!O42 -> 124.176 | Q21: =P21/(P21+O21) -> 0.25989443 | R21: =BC21/(1-Y21) -> 132.52715 | T21: =R21/(R21+O21) -> 0.27260819 | U21: =T21 -> 0.27260819 | V21: 40.536 | Y21: =V21/P21 -> 0.32643989 | AA21: =V21/(P21/(1-BE21)) -> 0.28878308 | AD21: =BB21-0.5*AP21+AI21 -> 757.43911 | AE21: =0.5*AP21 -> 84.468035 | AF21: =AD21-AE21 -> 672.97108 | AG21: =AD21 -> 757.43911 | AH21: =AG21-AI21 -> 613.27197 | AI21: =BC21/(1-Y21)+BD21 -> 144.16715 | AK21: =AL21+AM21 -> 841.90715 | AL21: =BB21 -> 697.74 | AM21: =AI21 -> 144.16715 | AN21: =AK21 -> 841.90715 | AO21: =AN21-AP21 -> 672.97108 | AP21: 168.93607 | AQ21: =AF21-AO21 -> 0 | AR21: =Data!AM21/Data!AK21 -> 0.17123877 | AS21: =Data!AI21/Data!AG21 -> 0.19033497 | AV21: ='[1]Assets(BoP)'!$D90 -> 808.5 | AW21: 25.8 | AX21: ='[1]Assets(BoP)'!$CI90 -> 0 | AY21: =BK21 -> 15.945 | AZ21: =AV21-AW21-AX21+AY21 -> 798.645 | BA21: 100.905 | BB21: =AZ21-BA21 -> 697.74 | BC21: =BA21-BD21 -> 89.265 | BD21: 11.64 | BE21: =BD21/BA21 -> 0.11535603 | BF21: 103.963 | BG21: =BC21/(1-Y21) -> 132.52715 | BI21: ='[1]Assets(BoP)'!$Q90 -> 44 | BK21: =BI21-BL21 -> 15.945 | BL21: 28.055 | BM21: 0 | BP21: 1998 | BQ21: =Data!AR21*WrightZucman!B42 -> 0.045100213 | BR21: =$BQ21*WrightZucman!C42/WrightZucman!$B42 -> 0.014911133 | BS21: =WrightZucman!C42*Data!AS21-BR21 -> 0.0016628586 | BT21: =$BQ21*WrightZucman!D42/WrightZucman!$B42 -> 0.010211499 | BU21: =$BQ21*WrightZucman!E42/WrightZucman!$B42 -> 0.0047410039 | BV21: =$BQ21*WrightZucman!F42/WrightZucman!$B42 -> 0.01098236 | BW21: =$BQ21*WrightZucman!G42/WrightZucman!$B42 -> 0.0042542167 | BX21: =BQ21-BR21-BT21-BU21-BV21-BW21 -> 0 | BZ21: =Data!AR21*WrightZucman!B42 -> 0.045100213 | CA21: =Data!D21*WrightZucman!B42 -> 0.076679292 | CB21: =Data!Q21*WrightZucman!B42 -> 0.068450001 | CC21: =WrightZucman!C42*Data!$Q21 -> 0.022631092 | CD21: =WrightZucman!D42*Data!$Q21 -> 0.015498311 | CE21: =WrightZucman!E42*Data!$Q21 -> 0.0071955696 | CF21: =WrightZucman!F42*Data!$Q21 -> 0.016668271 | CG21: =WrightZucman!G42*Data!$Q21 -> 0.0064567575 | CH21: =CB21-CC21-CD21-CE21-CF21-CG21 -> 1.2143064e-17 | CJ21: =CK21+CL21 -> 212.6 | CK21: 177.7 | CL21: 34.9 | CM21: =BC21*Y21/(1-Y21) -> 43.262148 | CN21: =(CJ21+CM21)/AD21 -> 0.33779896 | CO21: ='[1]Assets(BoP)'!$BN90 -> 0.3872544 | CQ21: =(O21+P21)/AD21 -> 0.63080186 | CR21: =P21/AI21 -> 0.86133354 | CS21: =O21/AL21 -> 0.50680483 | CT21: =O21/(AL21-0.5*AP21) -> 0.57660878 | CU21: =(O21+P21)/AD21 -> 0.63080186 | CV21: =(E21/1000000000)/AD21 -> 3.6640214e-07 | CW21: =(F21/1000)/(BC21/(1-Y21)) -> 0.67248334 | CX21: =((E21-F21)/1000000000)/O21 -> 5.3279249e-07 | CY21: =(F21/1000000000)/P21 -> 7.1770953e-07 | CZ21: =P21/(BC21/(1-Y21)) -> 0.93698538 | DA21: =(P21-V21)/BC21 -> 0.93698538 | DB21: =(F21/1000)/P21 -> 0.71770953
A22: 1999 | B22: 384134.6 | C22: 122131.04 | D22: 0.31793815 | E22: 362942.29 | F22: 119345.04 | G22: 0.32882651 | H22: 363307.26 | I22: 119346.73 | J22: 0.32850081 | K22: =C22/B22-D22 -> 0 | L22: =I22/H22-J22 -> 0 | M22: =F22/E22-G22 -> 0 | O22: =[3]TablePage!$D$6/1000 -> 408.638 | P22: =WrightZucman!O43 -> 141.956 | Q22: =P22/(P22+O22) -> 0.25782337 | R22: =BC22/(1-Y22) -> 162.98684 | T22: =R22/(R22+O22) -> 0.28512904 | U22: =T22 -> 0.28512904 | V22: 45.068 | W22: =166.191 -> 166.191 | X22: =W22/O22 -> 0.40669492 | Y22: =V22/P22 -> 0.31747866 | Z22: =(V22+W22)/(O22+P22) -> 0.38369288 | AA22: =V22/(P22/(1-BE22)) -> 0.28031559 | AB22: =(V22+W22)/(P22/(1-BE22)+O22) -> 0.37101129 | AD22: =BB22-0.5*AP22+AI22 -> 753.6868 | AE22: =0.5*AP22 -> 93.093049 | AF22: =AD22-AE22 -> 660.59375 | AG22: =AD22 -> 753.6868 | AH22: =AG22-AI22 -> 575.95195 | AI22: =BC22/(1-Y22)+BD22 -> 177.73484 | AK22: =AL22+AM22 -> 846.77984 | AL22: =BB22 -> 669.045 | AM22: =AI22 -> 177.73484 | AN22: =AK22 -> 846.77984 | AO22: =AN22-AP22 -> 660.59375 | AP22: 186.1861 | AQ22: =AF22-AO22 -> 0 | AR22: =Data!AM22/Data!AK22 -> 0.20989499 | AS22: =Data!AI22/Data!AG22 -> 0.23582056 | AV22: ='[1]Assets(BoP)'!$D91 -> 834.9 | AW22: 26.8 | AX22: ='[1]Assets(BoP)'!$CI91 -> 30.123 | AY22: =BK22 -> 17.058 | AZ22: =AV22-AW22-AX22+AY22 -> 795.035 | BA22: 125.99 | BB22: =AZ22-BA22 -> 669.045 | BC22: =BA22-BD22 -> 111.242 | BD22: 14.748 | BE22: =BD22/BA22 -> 0.11705691 | BF22: 130.512 | BG22: =BC22/(1-Y22) -> 162.98684 | BI22: ='[1]Assets(BoP)'!$Q91 -> 55 | BK22: 17.058 | BL22: 37.695 | BM22: =BI22-BK22-BL22 -> 0.247 | BP22: 1999 | BQ22: =Data!AR22*WrightZucman!B43 -> 0.050516091 | BR22: =$BQ22*WrightZucman!C43/WrightZucman!$B43 -> 0.016668166 | BS22: =WrightZucman!C43*Data!AS22-BR22 -> 0.0020588 | BT22: =$BQ22*WrightZucman!D43/WrightZucman!$B43 -> 0.0095339603 | BU22: =$BQ22*WrightZucman!E43/WrightZucman!$B43 -> 0.0052549155 | BV22: =$BQ22*WrightZucman!F43/WrightZucman!$B43 -> 0.011833171 | BW22: =$BQ22*WrightZucman!G43/WrightZucman!$B43 -> 0.0072258784 | BX22: =BQ22-BR22-BT22-BU22-BV22-BW22 -> 0 | BZ22: =Data!AR22*WrightZucman!B43 -> 0.050516091 | CA22: =Data!D22*WrightZucman!B43 -> 0.076519181 | CB22: =Data!Q22*WrightZucman!B43 -> 0.062051167 | CC22: =WrightZucman!C43*Data!$Q22 -> 0.020474251 | CD22: =WrightZucman!D43*Data!$Q22 -> 0.011710988 | CE22: =WrightZucman!E43*Data!$Q22 -> 0.0064548469 | CF22: =WrightZucman!F43*Data!$Q22 -> 0.014535211 | CG22: =WrightZucman!G43*Data!$Q22 -> 0.0088758686 | CH22: =CB22-CC22-CD22-CE22-CF22-CG22 -> 0 | CJ22: =CK22+CL22 -> 223.4 | CK22: 187.6 | CL22: 35.8 | CM22: =BC22*Y22/(1-Y22) -> 51.744844 | CN22: =(CJ22+CM22)/AD22 -> 0.36506523 | CO22: ='[1]Assets(BoP)'!$BN91 -> 0.39528368 | CQ22: =(O22+P22)/AD22 -> 0.73053423 | CR22: =P22/AI22 -> 0.79869539 | CS22: =O22/AL22 -> 0.61077805 | CT22: =O22/(AL22-0.5*AP22) -> 0.70950016 | CU22: =(O22+P22)/AD22 -> 0.73053423 | CV22: =(E22/1000000000)/AD22 -> 4.8155585e-07 | CW22: =(F22/1000)/(BC22/(1-Y22)) -> 0.73223729 | CX22: =((E22-F22)/1000000000)/O22 -> 5.961199e-07 | CY22: =(F22/1000000000)/P22 -> 8.4071857e-07 | CZ22: =P22/(BC22/(1-Y22)) -> 0.870966 | DA22: =(P22-V22)/BC22 -> 0.870966 | DB22: =(F22/1000)/P22 -> 0.84071857
A23: 2000 | B23: 453512.43 | C23: 155955.76 | D23: 0.34388421 | E23: 405764.15 | F23: 149293.38 | G23: 0.36793142 | H23: 419018.46 | I23: 151511.89 | J23: 0.36158762 | K23: =C23/B23-D23 -> 0 | L23: =I23/H23-J23 -> 0 | M23: =F23/E23-G23 -> 0 | O23: =[4]TablePage!$D$6/1000 -> 445.616 | P23: =WrightZucman!O44 -> 172.155 | Q23: =P23/(P23+O23) -> 0.27867122 | R23: =BC23/(1-Y23) -> 199.01084 | T23: =R23/(R23+O23) -> 0.30872254 | U23: =T23 -> 0.30872254 | V23: 59.801 | Y23: =V23/P23 -> 0.3473672 | AA23: =V23/(P23/(1-BE23)) -> 0.3115042 | AD23: =BB23-0.5*AP23+AI23 -> 716.23689 | AE23: =0.5*AP23 -> 94.264944 | AF23: =AD23-AE23 -> 621.97195 | AG23: =AD23 -> 716.23689 | AH23: =AG23-AI23 -> 502.27306 | AI23: =BC23/(1-Y23)+BD23 -> 213.96384 | AK23: =AL23+AM23 -> 810.50184 | AL23: =BB23 -> 596.538 | AM23: =AI23 -> 213.96384 | AN23: =AK23 -> 810.50184 | AO23: =AN23-AP23 -> 621.97195 | AP23: 188.52989 | AQ23: =AF23-AO23 -> 0 | AR23: =Data!AM23/Data!AK23 -> 0.26398933 | AS23: =Data!AI23/Data!AG23 -> 0.29873334 | AV23: ='[1]Assets(BoP)'!$D92 -> 786.6 | AW23: 31.4 | AX23: ='[1]Assets(BoP)'!$CI92 -> 33.473 | AY23: =BK23 -> 19.645 | AZ23: =AV23-AW23-AX23+AY23 -> 741.372 | BA23: 144.834 | BB23: =AZ23-BA23 -> 596.538 | BC23: =BA23-BD23 -> 129.881 | BD23: 14.953 | BE23: =BD23/BA23 -> 0.10324233 | BF23: 149.839 | BG23: =BC23/(1-Y23) -> 199.01084 | BI23: ='[1]Assets(BoP)'!$Q92 -> 55.9 | BK23: 19.645 | BL23: 36.071 | BM23: =BI23-BK23-BL23 -> 0.184 | BP23: 2000 | BQ23: =Data!AR23*WrightZucman!B44 -> 0.063835566 | BR23: =$BQ23*WrightZucman!C44/WrightZucman!$B44 -> 0.019140396 | BS23: =WrightZucman!C44*Data!AS23-BR23 -> 0.0025190944 | BT23: =$BQ23*WrightZucman!D44/WrightZucman!$B44 -> 0.011582071 | BU23: =$BQ23*WrightZucman!E44/WrightZucman!$B44 -> 0.0057335314 | BV23: =$BQ23*WrightZucman!F44/WrightZucman!$B44 -> 0.01449254 | BW23: =$BQ23*WrightZucman!G44/WrightZucman!$B44 -> 0.012887028 | BX23: =BQ23-BR23-BT23-BU23-BV23-BW23 -> 0 | BZ23: =Data!AR23*WrightZucman!B44 -> 0.063835566 | CA23: =Data!D23*WrightZucman!B44 -> 0.083155039 | CB23: =Data!Q23*WrightZucman!B44 -> 0.067385811 | CC23: =WrightZucman!C44*Data!$Q23 -> 0.020204898 | CD23: =WrightZucman!D44*Data!$Q23 -> 0.012226213 | CE23: =WrightZucman!E44*Data!$Q23 -> 0.0060524045 | CF23: =WrightZucman!F44*Data!$Q23 -> 0.015298549 | CG23: =WrightZucman!G44*Data!$Q23 -> 0.013603746 | CH23: =CB23-CC23-CD23-CE23-CF23-CG23 -> 0 | CJ23: =CK23+CL23 -> 229.3 | CK23: 194.1 | CL23: 35.2 | CM23: =BC23*Y23/(1-Y23) -> 69.129837 | CN23: =(CJ23+CM23)/AD23 -> 0.41666359 | CO23: ='[1]Assets(BoP)'!$BN92 -> 0.45339093 | CQ23: =(O23+P23)/AD23 -> 0.86252329 | CR23: =P23/AI23 -> 0.80459858 | CS23: =O23/AL23 -> 0.74700354 | CT23: =O23/(AL23-0.5*AP23) -> 0.88719869 | CU23: =(O23+P23)/AD23 -> 0.86252329 | CV23: =(E23/1000000000)/AD23 -> 5.6652227e-07 | CW23: =(F23/1000)/(BC23/(1-Y23)) -> 0.75017713 | CX23: =((E23-F23)/1000000000)/O23 -> 5.7554211e-07 | CY23: =(F23/1000000000)/P23 -> 8.6720326e-07 | CZ23: =P23/(BC23/(1-Y23)) -> 0.8650534 | DA23: =(P23-V23)/BC23 -> 0.8650534 | DB23: =(F23/1000)/P23 -> 0.86720326
A24: 2001 | B24: 334652.67 | C24: 129048.24 | D24: 0.38561842 | E24: 145674.41 | F24: 122113.2 | G24: 0.83826119 | H24: 269551.54 | I24: 127027.42 | J24: 0.47125465 | K24: =C24/B24-D24 -> 0 | L24: =I24/H24-J24 -> 0 | M24: =F24/E24-G24 -> 0 | O24: =[5]TablePage!$D$6/1000 -> 271.918 | P24: =WrightZucman!O45 -> 141.198 | Q24: =P24/(P24+O24) -> 0.34178778 | R24: =BC24/(1-Y24) -> 173.31503 | T24: =R24/(R24+O24) -> 0.38926813 | U24: =T24 -> 0.38926813 | V24: 55.214 | Y24: =V24/P24 -> 0.39103953 | AA24: =V24/(P24/(1-BE24)) -> 0.33757377 | AD24: =BB24-0.5*AP24+AI24 -> 687.6375 | AE24: =0.5*AP24 -> 96.600531 | AF24: =AD24-AE24 -> 591.03697 | AG24: =AD24 -> 687.6375 | AH24: =AG24-AI24 -> 497.60647 | AI24: =BC24/(1-Y24)+BD24 -> 190.03103 | AK24: =AL24+AM24 -> 784.23803 | AL24: =BB24 -> 594.207 | AM24: =AI24 -> 190.03103 | AN24: =AK24 -> 784.23803 | AO24: =AN24-AP24 -> 591.03697 | AP24: 193.20106 | AQ24: =AF24-AO24 -> 0 | AR24: =Data!AM24/Data!AK24 -> 0.24231295 | AS24: =Data!AI24/Data!AG24 -> 0.2763535 | AV24: ='[1]Assets(BoP)'!$D93 -> 758.7 | AW24: 29.2 | AX24: ='[1]Assets(BoP)'!$CI93 -> 34.164 | AY24: =BK24 -> 21.129 | AZ24: =AV24-AW24-AX24+AY24 -> 716.465 | BA24: 122.258 | BB24: =AZ24-BA24 -> 594.207 | BC24: =BA24-BD24 -> 105.542 | BD24: 16.716 | BE24: =BD24/BA24 -> 0.13672725 | BF24: 127.523 | BG24: =BC24/(1-Y24) -> 173.31503 | BI24: ='[1]Assets(BoP)'!$Q93 -> 13.9 | BK24: 21.129 | BL24: -7.415 | BM24: =BI24-BK24-BL24 -> 0.186 | BP24: 2001 | BQ24: =Data!AR24*WrightZucman!B45 -> 0.0653911 | BR24: =$BQ24*WrightZucman!C45/WrightZucman!$B45 -> 0.021818771 | BS24: =WrightZucman!C45*Data!AS24-BR24 -> 0.0030651395 | BT24: =$BQ24*WrightZucman!D45/WrightZucman!$B45 -> 0.011801769 | BU24: =$BQ24*WrightZucman!E45/WrightZucman!$B45 -> 0.0059583744 | BV24: =$BQ24*WrightZucman!F45/WrightZucman!$B45 -> 0.016972443 | BW24: =$BQ24*WrightZucman!G45/WrightZucman!$B45 -> 0.0088397427 | BX24: =BQ24-BR24-BT24-BU24-BV24-BW24 -> 0 | BZ24: =Data!AR24*WrightZucman!B45 -> 0.0653911 | CA24: =Data!D24*WrightZucman!B45 -> 0.10406383 | CB24: =Data!Q24*WrightZucman!B45 -> 0.092235595 | CC24: =WrightZucman!C45*Data!$Q24 -> 0.03077586 | CD24: =WrightZucman!D45*Data!$Q24 -> 0.016646656 | CE24: =WrightZucman!E45*Data!$Q24 -> 0.0084044191 | CF24: =WrightZucman!F45*Data!$Q24 -> 0.023940007 | CG24: =WrightZucman!G45*Data!$Q24 -> 0.012468653 | CH24: =CB24-CC24-CD24-CE24-CF24-CG24 -> 1.5612511e-17 | CJ24: =CK24+CL24 -> 166.5 | CK24: 137.6 | CL24: 28.9 | CM24: =BC24*Y24/(1-Y24) -> 67.773027 | CN24: =(CJ24+CM24)/AD24 -> 0.34069263 | CO24: ='[1]Assets(BoP)'!$BN93 -> 0.39225125 | CQ24: =(O24+P24)/AD24 -> 0.60077585 | CR24: =P24/AI24 -> 0.74302603 | CS24: =O24/AL24 -> 0.45761494 | CT24: =O24/(AL24-0.5*AP24) -> 0.5464519 | CU24: =(O24+P24)/AD24 -> 0.60077585 | CV24: =(E24/1000000000)/AD24 -> 2.1184768e-07 | CW24: =(F24/1000)/(BC24/(1-Y24)) -> 0.70457365 | CX24: =((E24-F24)/1000000000)/O24 -> 8.6648199e-08 | CY24: =(F24/1000000000)/P24 -> 8.6483663e-07 | CZ24: =P24/(BC24/(1-Y24)) -> 0.81468989 | DA24: =(P24-V24)/BC24 -> 0.81468989 | DB24: =(F24/1000)/P24 -> 0.86483663
